Workbook

Sheet Instrucciones
A1: BlackScale — Sistema de Scoring de Prospectos
A2: De 2.000 contactos a 500 mejores | Plataforma principal: LinkedIn Ads
A4: CÓMO FUNCIONA ESTA HOJA
A6: 1. Pega tus 2.000 contactos de Apollo en la hoja 'Contactos' (columnas B–J, azul claro)
A7: 2. El VA (o tú) llena las columnas K–R verificando señales en LinkedIn, Meta y Google (amarillo)
A8: 3. El Score y el Tier se calculan AUTOMÁTICAMENTE (verde claro)
A9: 4. La hoja 'Top 500' filtra automáticamente los mejores
A10: 5. La hoja 'Configuración' permite ajustar los pesos del scoring si quieres recalibrar
A12: CÓDIGO DE COLORES EN HOJA 'CONTACTOS'
A14: AZUL CLARO (col B–J) | B14: Datos que vienen de Apollo. Pegas y listo.
A15: AMARILLO (col K–R) | B15: Datos que llena el VA verificando señales en LinkedIn, Meta y Google.
A16: VERDE CLARO (col S–W) | B16: Score Tamaño, Score Industria, Score Cargo, Score Total y Tier — calculados AUTOMÁTICAMENTE. NO TOCAR.
A18: DEFINICIÓN DE TIERS
A20: Tier A — Score ≥ 12 | B20: Test manual esta semana. 30 mejores van directo.
A21: Tier B — Score 8 a 11 | B21: Cold email cuando tengas Smartlead. Cadencia 5 touches.
A22: Tier C — Score 6 a 7 | B22: Cold email volumen medio. Mensaje más genérico por industria.
A23: Descarte — Score < 6 | B23: Fuera de esta ronda. Considerar para nurturing pasivo.
A25: FLUJO RECOMENDADO
A27: Día 1 | B27: Pegar los 2.000 contactos en hoja 'Contactos'.
A28: Día 2-7 | B28: VA enriquece columnas K–R (5-7 días, ~$200 USD).
A29: Día 8 | B29: Aplicar filtro automático en hoja 'Top 500'. Validar tier A.
A30: Día 9 | B30: Arrancar test manual con 30 contactos top tier A.
A32: INSTRUCCIONES PARA EL VA
A34: Ver hoja 'Instrucciones VA' → | B34: Copia y pega esa hoja completa al VA.

Sheet Configuración
A1: Pesos del Scoring
A2: Edita los valores en columna B para recalibrar. El scoring se actualiza solo.
A4: Criterio | B4: Puntos | C4: Notas
A5: Pauta activa en LinkedIn Ads | B5: 12 | C5: Señal más fuerte. Ya invierte en plataforma. SUPER importante.
A6: Posts empresa: Semanal | B6: 12 | C6: Cuando 'Frecuencia posts' = 'Semanal'
A7: Posts empresa: Mensual | B7: 4 | C7: Cuando 'Frecuencia posts' = 'Mensual'
A8: Decision maker activo en LinkedIn (30 días) | B8: 12 | C8: Si publicó o comentó algo último mes
A9: Pauta activa en Meta Ads | B9: 4 | C9: Verificable en facebook.com/ads/library
A10: Pauta activa en Google Ads | B10: 8 | C10: Verificable en adstransparency.google.com
A11: Marketing Manager sin Head/Director | B11: 8 | C11: Equipo sub-estructurado, listo para tercerizar
A12: Vacante abierta en Marketing | B12: 8 | C12: Ya está intentando solucionar el dolor
A15: Score máximo posible | B15: =SUM(B5:B12)+B23+B27+B31-B7 -> 100 | C15: Asume Semanal + Cargo CEO/CMO + Tamaño 1-10 + Industria Tech
A18: Umbrales de Tier
A19: Tier A (mínimo) | B19: 60
A20: Tier B (mínimo) | B20: 40
A21: Tier C (mínimo) | B21: 24
A23: Tamaño empresa: 1-10 empleados | B23: 12 | C23: Startup / micro empresa — alta probabilidad de tercerizar marketing
A24: Tamaño empresa: 11-50 empleados | B24: 4 | C24: Empresa pequeña — buen fit para BlackScale
A25: Tamaño empresa: 51-200 empleados | B25: 0 | C25: Mediana empresa — ciclo de venta más largo
A27: Industria: Tech / SaaS / IT / Fintech (prioridad alta) | B27: 12 | C27: Mayor presupuesto para marketing digital
A28: Industria: Otras industrias | B28: 4 | C28: Prioridad estándar — menor probabilidad de fit inmediato
A30: Cargo del decisor | B30: Puntos | C30: Criterio de relevancia para contratar agencia
A31: Cargo: CEO / Founder / Owner / Director General / Presidente | B31: 12 | C31: Decisor final en empresas medianas/pequeñas — máxima autoridad
A32: Cargo: CMO / VP Marketing / Director de Marketing / Head of Marketing | B32: 12 | C32: Comprador directo del servicio — es su área
A33: Cargo: Marketing Manager / Gerente de Marketing / Growth / Demand Gen | B33: 8 | C33: Influenciador clave — puede recomendar o liderar la decisión
A34: Cargo: COO / CFO / CTO / Gerente General / General Manager | B34: 4 | C34: Involucrado en aprobación de presupuesto pero no es su área directa
A35: Cargo: Otro (Ventas, Ops, Técnico, etc.) | B35: 0 | C35: Bajo poder de decisión sobre marketing

Sheet Contactos
A1: h | B1: Nombre | C1: Cargo | D1: Empresa | E1: Email | F1: LinkedIn URL persona | G1: LinkedIn URL empresa | H1: Web empresa | I1: Industria | J1: Tamaño empresa | K1: Pauta LinkedIn | L1: Frecuencia posts empresa | M1: Decision maker activo LI | N1: Pauta Meta | O1: Pauta Google | P1: Marketing Manager sin Head | Q1: Vacante Marketing | R1: Notas | S1: Score Tamaño | T1: Score Industria | U1: Score Cargo | V1: Score | W1: Tier
A2: Auto | K2: VA llena | L2: VA llena | M2: VA llena | N2: VA llena | O2: VA llena | P2: VA llena | Q2: VA llena | R2: VA llena | S2: Auto | T2: Auto | U2: Auto | V2: Auto | W2: Auto
A3: =IF(B3="","",ROW()-2) -> 1 | B3: Mario | C3: Co-Founder & COO | D3: Plataform | E3: mario@plataform.com | F3: http://www.linkedin.com/in/mario-jose-marquez-olier | G3: http://www.linkedin.com/company/plataform | H3: https://plataform.com | I3: financial services | J3: 44 | K3: Sí | L3: Semanal | M3: Sí | N3: Sí | O3: Sí | P3: No | Q3: No | S3: =IF(B3="","",IF(ISNUMBER(J3),IF(J3<=10,'Configuración'!$B$23,IF(J3<=50,'Configuración'!$B$24,IF(J3<=200,'Configuración'!$B$25,0))),0)) -> 4 | T3: =IF(B3="","",IF(ISNUMBER(SEARCH("information technology",I3))+ISNUMBER(SEARCH("software",I3))+ISNUMBER(SEARCH("internet",I3))+ISNUMBER(SEARCH("computer",I3))+ISNUMBER(SEARCH("saas",I3))+ISNUMBER(SEARCH("fintech",I3))+ISNUMBER(SEARCH("information services",I3))+ISNUMBER(SEARCH("telecommunications",I3))>0,'Configuración'!$B$27,'Configuración'!$B$28)) -> 4 | U3: =IF(B3="","",IF(ISNUMBER(SEARCH("CEO",C3))+ISNUMBER(SEARCH("Founder",C3))+ISNUMBER(SEARCH("Owner",C3))+ISNUMBER(SEARCH("Dueño",C3))+ISNUMBER(SEARCH("Director General",C3))+ISNUMBER(SEARCH("Presidente",C3))+ISNUMBER(SEARCH("President",C3))>0,'Configuración'!$B$31,IF(ISNUMBER(SEARCH("CMO",C3))+ISNUMBER(SEARCH("Chief Marketing",C3))+ISNUMBER(SEARCH("VP Marketing",C3))+ISNUMBER(SEARCH("Director de Marketing",C3))+ISNUMBER(SEARCH("Director Marketing",C3))+ISNUMBER(SEARCH("Head of Marketing",C3))+ISNUMBER(SEARCH("Head Marketing",C3))>0,'Configuración'!$B$32,IF(ISNUMBER(SEARCH("Marketing Manager",C3))+ISNUMBER(SEARCH("Gerente de Marketing",C3))+ISNUMBER(SEARCH("Growth Manager",C3))+ISNUMBER(SEARCH("Demand Gen",C3))+ISNUMBER(SEARCH("Marketing Lead",C3))>0,'Configuración'!$B$33,IF(ISNUMBER(SEARCH("COO",C3))+ISNUMBER(SEARCH("CFO",C3))+ISNUMBER(SEARCH("CTO",C3))+ISNUMBER(SEARCH("Chief Operating",C3))+ISNUMBER(SEARCH("Chief Financial",C3))+ISNUMBER(SEARCH("Gerente General",C3))+ISNUMBER(SEARCH("General Manager",C3))>0,'Configuración'!$B$34,'Configuración'!$B$35))))) -> 12 | V3: =IF(B3="","",IF(K3="Sí",'Configuración'!$B$5,0)+IF(L3="Semanal",'Configuración'!$B$6,IF(L3="Mensual",'Configuración'!$B$7,0))+IF(M3="Sí",'Configuración'!$B$8,0)+IF(N3="Sí",'Configuración'!$B$9,0)+IF(O3="Sí",'Configuración'!$B$10,0)+IF(P3="Sí",'Configuración'!$B$11,0)+IF(Q3="Sí",'Configuración'!$B$12,0)+S3+T3+U3) -> 68 | W3: =IF(B3="","",IF(V3>='Configuración'!$B$19,"A",IF(V3>='Configuración'!$B$20,"B",IF(V3>='Configuración'!$B$21,"C","Descarte")))) -> A
A4: =IF(B4="","",ROW()-2) -> 2 | B4: Daniel | C4: CEO & Founder | D4: Talk Eva | E4: dani@talkeva.com | F4: http://www.linkedin.com/in/daniel-gonz%c3%a1lez-rico-65366ab1 | G4: http://www.linkedin.com/company/talk-eva | H4: https://talkeva.com | I4: information technology & services | J4: 2 | K4: No | L4: Inactivo | M4: Sí | N4: No | O4: No | P4: No | Q4: No | R4: Posible Tier 1 por ser Startup y el CEO es experto en marketing digital | S4: =IF(B4="","",IF(ISNUMBER(J4),IF(J4<=10,'Configuración'!$B$23,IF(J4<=50,'Configuración'!$B$24,IF(J4<=200,'Configuración'!$B$25,0))),0)) -> 12 | T4: =IF(B4="","",IF(ISNUMBER(SEARCH("information technology",I4))+ISNUMBER(SEARCH("software",I4))+ISNUMBER(SEARCH("internet",I4))+ISNUMBER(SEARCH("computer",I4))+ISNUMBER(SEARCH("saas",I4))+ISNUMBER(SEARCH("fintech",I4))+ISNUMBER(SEARCH("information services",I4))+ISNUMBER(SEARCH("telecommunications",I4))>0,'Configuración'!$B$27,'Configuración'!$B$28)) -> 12 | U4: =IF(B4="","",IF(ISNUMBER(SEARCH("CEO",C4))+ISNUMBER(SEARCH("Founder",C4))+ISNUMBER(SEARCH("Owner",C4))+ISNUMBER(SEARCH("Dueño",C4))+ISNUMBER(SEARCH("Director General",C4))+ISNUMBER(SEARCH("Presidente",C4))+ISNUMBER(SEARCH("President",C4))>0,'Configuración'!$B$31,IF(ISNUMBER(SEARCH("CMO",C4))+ISNUMBER(SEARCH("Chief Marketing",C4))+ISNUMBER(SEARCH("VP Marketing",C4))+ISNUMBER(SEARCH("Director de Marketing",C4))+ISNUMBER(SEARCH("Director Marketing",C4))+ISNUMBER(SEARCH("Head of Marketing",C4))+ISNUMBER(SEARCH("Head Marketing",C4))>0,'Configuración'!$B$32,IF(ISNUMBER(SEARCH("Marketing Manager",C4))+ISNUMBER(SEARCH("Gerente de Marketing",C4))+ISNUMBER(SEARCH("Growth Manager",C4))+ISNUMBER(SEARCH("Demand Gen",C4))+ISNUMBER(SEARCH("Marketing Lead",C4))>0,'Configuración'!$B$33,IF(ISNUMBER(SEARCH("COO",C4))+ISNUMBER(SEARCH("CFO",C4))+ISNUMBER(SEARCH("CTO",C4))+ISNUMBER(SEARCH("Chief Operating",C4))+ISNUMBER(SEARCH("Chief Financial",C4))+ISNUMBER(SEARCH("Gerente General",C4))+ISNUMBER(SEARCH("General Manager",C4))>0,'Configuración'!$B$34,'Configuración'!$B$35))))) -> 12 | V4: =IF(B4="","",IF(K4="Sí",'Configuración'!$B$5,0)+IF(L4="Semanal",'Configuración'!$B$6,IF(L4="Mensual",'Configuración'!$B$7,0))+IF(M4="Sí",'Configuración'!$B$8,0)+IF(N4="Sí",'Configuración'!$B$9,0)+IF(O4="Sí",'Configuración'!$B$10,0)+IF(P4="Sí",'Configuración'!$B$11,0)+IF(Q4="Sí",'Configuración'!$B$12,0)+S4+T4+U4) -> 48 | W4: =IF(B4="","",IF(V4>='Configuración'!$B$19,"A",IF(V4>='Configuración'!$B$20,"B",IF(V4>='Configuración'!$B$21,"C","Descarte")))) -> B
A5: =IF(B5="","",ROW()-2) -> 3 | B5: Viviana | C5: CEO | D5: OfficeFacil | E5: vbecerra@officefacil.com | F5: http://www.linkedin.com/in/viviana-becerra-239364322 | G5: http://www.linkedin.com/company/officefacil-com | H5: https://officefacil.com | I5: professional training & coaching | J5: 2 | K5: Sí | L5: Inactivo | M5: Sí | N5: No | O5: No | P5: Sí | Q5: No | S5: =IF(B5="","",IF(ISNUMBER(J5),IF(J5<=10,'Configuración'!$B$23,IF(J5<=50,'Configuración'!$B$24,IF(J5<=200,'Configuración'!$B$25,0))),0)) -> 12 | T5: =IF(B5="","",IF(ISNUMBER(SEARCH("information technology",I5))+ISNUMBER(SEARCH("software",I5))+ISNUMBER(SEARCH("internet",I5))+ISNUMBER(SEARCH("computer",I5))+ISNUMBER(SEARCH("saas",I5))+ISNUMBER(SEARCH("fintech",I5))+ISNUMBER(SEARCH("information services",I5))+ISNUMBER(SEARCH("telecommunications",I5))>0,'Configuración'!$B$27,'Configuración'!$B$28)) -> 4 | U5: =IF(B5="","",IF(ISNUMBER(SEARCH("CEO",C5))+ISNUMBER(SEARCH("Founder",C5))+ISNUMBER(SEARCH("Owner",C5))+ISNUMBER(SEARCH("Dueño",C5))+ISNUMBER(SEARCH("Director General",C5))+ISNUMBER(SEARCH("Presidente",C5))+ISNUMBER(SEARCH("President",C5))>0,'Configuración'!$B$31,IF(ISNUMBER(SEARCH("CMO",C5))+ISNUMBER(SEARCH("Chief Marketing",C5))+ISNUMBER(SEARCH("VP Marketing",C5))+ISNUMBER(SEARCH("Director de Marketing",C5))+ISNUMBER(SEARCH("Director Marketing",C5))+ISNUMBER(SEARCH("Head of Marketing",C5))+ISNUMBER(SEARCH("Head Marketing",C5))>0,'Configuración'!$B$32,IF(ISNUMBER(SEARCH("Marketing Manager",C5))+ISNUMBER(SEARCH("Gerente de Marketing",C5))+ISNUMBER(SEARCH("Growth Manager",C5))+ISNUMBER(SEARCH("Demand Gen",C5))+ISNUMBER(SEARCH("Marketing Lead",C5))>0,'Configuración'!$B$33,IF(ISNUMBER(SEARCH("COO",C5))+ISNUMBER(SEARCH("CFO",C5))+ISNUMBER(SEARCH("CTO",C5))+ISNUMBER(SEARCH("Chief Operating",C5))+ISNUMBER(SEARCH("Chief Financial",C5))+ISNUMBER(SEARCH("Gerente General",C5))+ISNUMBER(SEARCH("General Manager",C5))>0,'Configuración'!$B$34,'Configuración'!$B$35))))) -> 12 | V5: =IF(B5="","",IF(K5="Sí",'Configuración'!$B$5,0)+IF(L5="Semanal",'Configuración'!$B$6,IF(L5="Mensual",'Configuración'!$B$7,0))+IF(M5="Sí",'Configuración'!$B$8,0)+IF(N5="Sí",'Configuración'!$B$9,0)+IF(O5="Sí",'Configuración'!$B$10,0)+IF(P5="Sí",'Configuración'!$B$11,0)+IF(Q5="Sí",'Configuración'!$B$12,0)+S5+T5+U5) -> 60 | W5: =IF(B5="","",IF(V5>='Configuración'!$B$19,"A",IF(V5>='Configuración'!$B$20,"B",IF(V5>='Configuración'!$B$21,"C","Descarte")))) -> A
A6: =IF(B6="","",ROW()-2) -> 4 | B6: Carlos | C6: CEO - Cofundador | D6: Faroo Legal | E6: carlosfarias@faroolegal.com | F6: http://www.linkedin.com/in/carlos-felipe-arias-avila-6675b98a | G6: http://www.linkedin.com/company/faroolegal | H6: https://faroolegal.com | I6: legal services | J6: 11 | K6: No | L6: Semanal | M6: Sí | N6: No | O6: No | P6: Sí | Q6: No | S6: =IF(B6="","",IF(ISNUMBER(J6),IF(J6<=10,'Configuración'!$B$23,IF(J6<=50,'Configuración'!$B$24,IF(J6<=200,'Configuración'!$B$25,0))),0)) -> 4 | T6: =IF(B6="","",IF(ISNUMBER(SEARCH("information technology",I6))+ISNUMBER(SEARCH("software",I6))+ISNUMBER(SEARCH("internet",I6))+ISNUMBER(SEARCH("computer",I6))+ISNUMBER(SEARCH("saas",I6))+ISNUMBER(SEARCH("fintech",I6))+ISNUMBER(SEARCH("information services",I6))+ISNUMBER(SEARCH("telecommunications",I6))>0,'Configuración'!$B$27,'Configuración'!$B$28)) -> 4 | U6: =IF(B6="","",IF(ISNUMBER(SEARCH("CEO",C6))+ISNUMBER(SEARCH("Founder",C6))+ISNUMBER(SEARCH("Owner",C6))+ISNUMBER(SEARCH("Dueño",C6))+ISNUMBER(SEARCH("Director General",C6))+ISNUMBER(SEARCH("Presidente",C6))+ISNUMBER(SEARCH("President",C6))>0,'Configuración'!$B$31,IF(ISNUMBER(SEARCH("CMO",C6))+ISNUMBER(SEARCH("Chief Marketing",C6))+ISNUMBER(SEARCH("VP Marketing",C6))+ISNUMBER(SEARCH("Director de Marketing",C6))+ISNUMBER(SEARCH("Director Marketing",C6))+ISNUMBER(SEARCH("Head of Marketing",C6))+ISNUMBER(SEARCH("Head Marketing",C6))>0,'Configuración'!$B$32,IF(ISNUMBER(SEARCH("Marketing Manager",C6))+ISNUMBER(SEARCH("Gerente de Marketing",C6))+ISNUMBER(SEARCH("Growth Manager",C6))+ISNUMBER(SEARCH("Demand Gen",C6))+ISNUMBER(SEARCH("Marketing Lead",C6))>0,'Configuración'!$B$33,IF(ISNUMBER(SEARCH("COO",C6))+ISNUMBER(SEARCH("CFO",C6))+ISNUMBER(SEARCH("CTO",C6))+ISNUMBER(SEARCH("Chief Operating",C6))+ISNUMBER(SEARCH("Chief Financial",C6))+ISNUMBER(SEARCH("Gerente General",C6))+ISNUMBER(SEARCH("General Manager",C6))>0,'Configuración'!$B$34,'Configuración'!$B$35))))) -> 12 | V6: =IF(B6="","",IF(K6="Sí",'Configuración'!$B$5,0)+IF(L6="Semanal",'Configuración'!$B$6,IF(L6="Mensual",'Configuración'!$B$7,0))+IF(M6="Sí",'Configuración'!$B$8,0)+IF(N6="Sí",'Configuración'!$B$9,0)+IF(O6="Sí",'Configuración'!$B$10,0)+IF(P6="Sí",'Configuración'!$B$11,0)+IF(Q6="Sí",'Configuración'!$B$12,0)+S6+T6+U6) -> 52 | W6: =IF(B6="","",IF(V6>='Configuración'!$B$19,"A",IF(V6>='Configuración'!$B$20,"B",IF(V6>='Configuración'!$B$21,"C","Descarte")))) -> B
A7: =IF(B7="","",ROW()-2) -> 5 | B7: Daniel | C7: Chief Executive Officer | D7: CAXDAC | E7: danino@caxdac.com | F7: http://www.linkedin.com/in/daniel-ni%c3%b1o-tarazona-89980082 | G7: http://www.linkedin.com/company/caxdac-caja-de-auxilios-y-de-prestaciones-de-acdac | H7: https://caxdac.com | I7: financial services | J7: 35 | K7: No | L7: Inactivo | M7: No | N7: No | O7: No | P7: No | Q7: No | S7: =IF(B7="","",IF(ISNUMBER(J7),IF(J7<=10,'Configuración'!$B$23,IF(J7<=50,'Configuración'!$B$24,IF(J7<=200,'Configuración'!$B$25,0))),0)) -> 4 | T7: =IF(B7="","",IF(ISNUMBER(SEARCH("information technology",I7))+ISNUMBER(SEARCH("software",I7))+ISNUMBER(SEARCH("internet",I7))+ISNUMBER(SEARCH("computer",I7))+ISNUMBER(SEARCH("saas",I7))+ISNUMBER(SEARCH("fintech",I7))+ISNUMBER(SEARCH("information services",I7))+ISNUMBER(SEARCH("telecommunications",I7))>0,'Configuración'!$B$27,'Configuración'!$B$28)) -> 4 | U7: =IF(B7="","",IF(ISNUMBER(SEARCH("CEO",C7))+ISNUMBER(SEARCH("Founder",C7))+ISNUMBER(SEARCH("Owner",C7))+ISNUMBER(SEARCH("Dueño",C7))+ISNUMBER(SEARCH("Director General",C7))+ISNUMBER(SEARCH("Presidente",C7))+ISNUMBER(SEARCH("President",C7))>0,'Configuración'!$B$31,IF(ISNUMBER(SEARCH("CMO",C7))+ISNUMBER(SEARCH("Chief Marketing",C7))+ISNUMBER(SEARCH("VP Marketing",C7))+ISNUMBER(SEARCH("Director de Marketing",C7))+ISNUMBER(SEARCH("Director Marketing",C7))+ISNUMBER(SEARCH("Head of Marketing",C7))+ISNUMBER(SEARCH("Head Marketing",C7))>0,'Configuración'!$B$32,IF(ISNUMBER(SEARCH("Marketing Manager",C7))+ISNUMBER(SEARCH("Gerente de Marketing",C7))+ISNUMBER(SEARCH("Growth Manager",C7))+ISNUMBER(SEARCH("Demand Gen",C7))+ISNUMBER(SEARCH("Marketing Lead",C7))>0,'Configuración'!$B$33,IF(ISNUMBER(SEARCH("COO",C7))+ISNUMBER(SEARCH("CFO",C7))+ISNUMBER(SEARCH("CTO",C7))+ISNUMBER(SEARCH("Chief Operating",C7))+ISNUMBER(SEARCH("Chief Financial",C7))+ISNUMBER(SEARCH("Gerente General",C7))+ISNUMBER(SEARCH("General Manager",C7))>0,'Configuración'!$B$34,'Configuración'!$B$35))))) -> 0 | V7: =IF(B7="","",IF(K7="Sí",'Configuración'!$B$5,0)+IF(L7="Semanal",'Configuración'!$B$6,IF(L7="Mensual",'Configuración'!$B$7,0))+IF(M7="Sí",'Configuración'!$B$8,0)+IF(N7="Sí",'Configuración'!$B$9,0)+IF(O7="Sí",'Configuración'!$B$10,0)+IF(P7="Sí",'Configuración'!$B$11,0)+IF(Q7="Sí",'Configuración'!$B$12,0)+S7+T7+U7) -> 8 | W7: =IF(B7="","",IF(V7>='Configuración'!$B$19,"A",IF(V7>='Configuración'!$B$20,"B",IF(V7>='Configuración'!$B$21,"C","Descarte")))) -> Descarte
A8: =IF(B8="","",ROW()-2) -> 6 | B8: Daniel | C8: Co - Founder | D8: Inkoms | E8: daniel@inkoms.com | F8: http://www.linkedin.com/in/danielgomezvelez | G8: http://www.linkedin.com/company/inkoms | H8: https://inkoms.com | I8: investment management | J8: 4 | K8: No | L8: Inactivo | M8: No | N8: No | O8: No | Q8: No | S8: =IF(B8="","",IF(ISNUMBER(J8),IF(J8<=10,'Configuración'!$B$23,IF(J8<=50,'Configuración'!$B$24,IF(J8<=200,'Configuración'!$B$25,0))),0)) -> 12 | T8: =IF(B8="","",IF(ISNUMBER(SEARCH("information technology",I8))+ISNUMBER(SEARCH("software",I8))+ISNUMBER(SEARCH("internet",I8))+ISNUMBER(SEARCH("computer",I8))+ISNUMBER(SEARCH("saas",I8))+ISNUMBER(SEARCH("fintech",I8))+ISNUMBER(SEARCH("information services",I8))+ISNUMBER(SEARCH("telecommunications",I8))>0,'Configuración'!$B$27,'Configuración'!$B$28)) -> 4 | U8: =IF(B8="","",IF(ISNUMBER(SEARCH("CEO",C8))+ISNUMBER(SEARCH("Founder",C8))+ISNUMBER(SEARCH("Owner",C8))+ISNUMBER(SEARCH("Dueño",C8))+ISNUMBER(SEARCH("Director General",C8))+ISNUMBER(SEARCH("Presidente",C8))+ISNUMBER(SEARCH("President",C8))>0,'Configuración'!$B$31,IF(ISNUMBER(SEARCH("CMO",C8))+ISNUMBER(SEARCH("Chief Marketing",C8))+ISNUMBER(SEARCH("VP Marketing",C8))+ISNUMBER(SEARCH("Director de Marketing",C8))+ISNUMBER(SEARCH("Director Marketing",C8))+ISNUMBER(SEARCH("Head of Marketing",C8))+ISNUMBER(SEARCH("Head Marketing",C8))>0,'Configuración'!$B$32,IF(ISNUMBER(SEARCH("Marketing Manager",C8))+ISNUMBER(SEARCH("Gerente de Marketing",C8))+ISNUMBER(SEARCH("Growth Manager",C8))+ISNUMBER(SEARCH("Demand Gen",C8))+ISNUMBER(SEARCH("Marketing Lead",C8))>0,'Configuración'!$B$33,IF(ISNUMBER(SEARCH("COO",C8))+ISNUMBER(SEARCH("CFO",C8))+ISNUMBER(SEARCH("CTO",C8))+ISNUMBER(SEARCH("Chief Operating",C8))+ISNUMBER(SEARCH("Chief Financial",C8))+ISNUMBER(SEARCH("Gerente General",C8))+ISNUMBER(SEARCH("General Manager",C8))>0,'Configuración'!$B$34,'Configuración'!$B$35))))) -> 12 | V8: =IF(B8="","",IF(K8="Sí",'Configuración'!$B$5,0)+IF(L8="Semanal",'Configuración'!$B$6,IF(L8="Mensual",'Configuración'!$B$7,0))+IF(M8="Sí",'Configuración'!$B$8,0)+IF(N8="Sí",'Configuración'!$B$9,0)+IF(O8="Sí",'Configuración'!$B$10,0)+IF(P8="Sí",'Configuración'!$B$11,0)+IF(Q8="Sí",'Configuración'!$B$12,0)+S8+T8+U8) -> 28 | W8: =IF(B8="","",IF(V8>='Configuración'!$B$19,"A",IF(V8>='Configuración'!$B$20,"B",IF(V8>='Configuración'!$B$21,"C","Descarte")))) -> C
A9: =IF(B9="","",ROW()-2) -> 7 | B9: Sebastian | C9: Head of Sales Colombia | D9: Finnecto | E9: sebastian.gasca@finnecto.com | F9: http://www.linkedin.com/in/sebastian-gasca | G9: http://www.linkedin.com/company/finnecto | H9: https://finnecto.com | I9: information technology & services | J9: 18 | K9: No | L9: Semanal | M9: Sí | N9: No | O9: No | Q9: No | S9: =IF(B9="","",IF(ISNUMBER(J9),IF(J9<=10,'Configuración'!$B$23,IF(J9<=50,'Configuración'!$B$24,IF(J9<=200,'Configuración'!$B$25,0))),0)) -> 4 | T9: =IF(B9="","",IF(ISNUMBER(SEARCH("information technology",I9))+ISNUMBER(SEARCH("software",I9))+ISNUMBER(SEARCH("internet",I9))+ISNUMBER(SEARCH("computer",I9))+ISNUMBER(SEARCH("saas",I9))+ISNUMBER(SEARCH("fintech",I9))+ISNUMBER(SEARCH("information services",I9))+ISNUMBER(SEARCH("telecommunications",I9))>0,'Configuración'!$B$27,'Configuración'!$B$28)) -> 12 | U9: =IF(B9="","",IF(ISNUMBER(SEARCH("CEO",C9))+ISNUMBER(SEARCH("Founder",C9))+ISNUMBER(SEARCH("Owner",C9))+ISNUMBER(SEARCH("Dueño",C9))+ISNUMBER(SEARCH("Director General",C9))+ISNUMBER(SEARCH("Presidente",C9))+ISNUMBER(SEARCH("President",C9))>0,'Configuración'!$B$31,IF(ISNUMBER(SEARCH("CMO",C9))+ISNUMBER(SEARCH("Chief Marketing",C9))+ISNUMBER(SEARCH("VP Marketing",C9))+ISNUMBER(SEARCH("Director de Marketing",C9))+ISNUMBER(SEARCH("Director Marketing",C9))+ISNUMBER(SEARCH("Head of Marketing",C9))+ISNUMBER(SEARCH("Head Marketing",C9))>0,'Configuración'!$B$32,IF(ISNUMBER(SEARCH("Marketing Manager",C9))+ISNUMBER(SEARCH("Gerente de Marketing",C9))+ISNUMBER(SEARCH("Growth Manager",C9))+ISNUMBER(SEARCH("Demand Gen",C9))+ISNUMBER(SEARCH("Marketing Lead",C9))>0,'Configuración'!$B$33,IF(ISNUMBER(SEARCH("COO",C9))+ISNUMBER(SEARCH("CFO",C9))+ISNUMBER(SEARCH("CTO",C9))+ISNUMBER(SEARCH("Chief Operating",C9))+ISNUMBER(SEARCH("Chief Financial",C9))+ISNUMBER(SEARCH("Gerente General",C9))+ISNUMBER(SEARCH("General Manager",C9))>0,'Configuración'!$B$34,'Configuración'!$B$35))))) -> 0 | V9: =IF(B9="","",IF(K9="Sí",'Configuración'!$B$5,0)+IF(L9="Semanal",'Configuración'!$B$6,IF(L9="Mensual",'Configuración'!$B$7,0))+IF(M9="Sí",'Configuración'!$B$8,0)+IF(N9="Sí",'Configuración'!$B$9,0)+IF(O9="Sí",'Configuración'!$B$10,0)+IF(P9="Sí",'Configuración'!$B$11,0)+IF(Q9="Sí",'Configuración'!$B$12,0)+S9+T9+U9) -> 40 | W9: =IF(B9="","",IF(V9>='Configuración'!$B$19,"A",IF(V9>='Configuración'!$B$20,"B",IF(V9>='Configuración'!$B$21,"C","Descarte")))) -> B
A10: =IF(B10="","",ROW()-2) -> 8 | B10: Jorge | C10: CEO | D10: ELSA | E10: juribe@elsa360.com | F10: http://www.linkedin.com/in/jorge-uribe-cardozo-16466740 | G10: http://www.linkedin.com/company/elsa360 | H10: https://elsa360.com | I10: sports | J10: 7 | K10: No | L10: Mensual | M10: Sí | N10: No | O10: No | Q10: No | S10: =IF(B10="","",IF(ISNUMBER(J10),IF(J10<=10,'Configuración'!$B$23,IF(J10<=50,'Configuración'!$B$24,IF(J10<=200,'Configuración'!$B$25,0))),0)) -> 12 | T10: =IF(B10="","",IF(ISNUMBER(SEARCH("information technology",I10))+ISNUMBER(SEARCH("software",I10))+ISNUMBER(SEARCH("internet",I10))+ISNUMBER(SEARCH("computer",I10))+ISNUMBER(SEARCH("saas",I10))+ISNUMBER(SEARCH("fintech",I10))+ISNUMBER(SEARCH("information services",I10))+ISNUMBER(SEARCH("telecommunications",I10))>0,'Configuración'!$B$27,'Configuración'!$B$28)) -> 4 | U10: =IF(B10="","",IF(ISNUMBER(SEARCH("CEO",C10))+ISNUMBER(SEARCH("Founder",C10))+ISNUMBER(SEARCH("Owner",C10))+ISNUMBER(SEARCH("Dueño",C10))+ISNUMBER(SEARCH("Director General",C10))+ISNUMBER(SEARCH("Presidente",C10))+ISNUMBER(SEARCH("President",C10))>0,'Configuración'!$B$31,IF(ISNUMBER(SEARCH("CMO",C10))+ISNUMBER(SEARCH("Chief Marketing",C10))+ISNUMBER(SEARCH("VP Marketing",C10))+ISNUMBER(SEARCH("Director de Marketing",C10))+ISNUMBER(SEARCH("Director Marketing",C10))+ISNUMBER(SEARCH("Head of Marketing",C10))+ISNUMBER(SEARCH("Head Marketing",C10))>0,'Configuración'!$B$32,IF(ISNUMBER(SEARCH("Marketing Manager",C10))+ISNUMBER(SEARCH("Gerente de Marketing",C10))+ISNUMBER(SEARCH("Growth Manager",C10))+ISNUMBER(SEARCH("Demand Gen",C10))+ISNUMBER(SEARCH("Marketing Lead",C10))>0,'Configuración'!$B$33,IF(ISNUMBER(SEARCH("COO",C10))+ISNUMBER(SEARCH("CFO",C10))+ISNUMBER(SEARCH("CTO",C10))+ISNUMBER(SEARCH("Chief Operating",C10))+ISNUMBER(SEARCH("Chief Financial",C10))+ISNUMBER(SEARCH("Gerente General",C10))+ISNUMBER(SEARCH("General Manager",C10))>0,'Configuración'!$B$34,'Configuración'!$B$35))))) -> 12 | V10: =IF(B10="","",IF(K10="Sí",'Configuración'!$B$5,0)+IF(L10="Semanal",'Configuración'!$B$6,IF(L10="Mensual",'Configuración'!$B$7,0))+IF(M10="Sí",'Configuración'!$B$8,0)+IF(N10="Sí",'Configuración'!$B$9,0)+IF(O10="Sí",'Configuración'!$B$10,0)+IF(P10="Sí",'Configuración'!$B$11,0)+IF(Q10="Sí",'Configuración'!$B$12,0)+S10+T10+U10) -> 44 | W10: =IF(B10="","",IF(V10>='Configuración'!$B$19,"A",IF(V10>='Configuración'!$B$20,"B",IF(V10>='Configuración'!$B$21,"C","Descarte")))) -> B
A11: =IF(B11="","",ROW()-2) -> 9 | B11: Juan | C11: Founder | D11: Complemento 360 Colombia | E11: jacobo.paramo@complemento360.com | F11: http://www.linkedin.com/in/juan-jacobo-p%c3%a1ramo-b47a1322 | G11: http://www.linkedin.com/company/complemento360colombia | H11: https://complemento360.com | I11: information technology & services | J11: 30 | K11: No | L11: Semanal | M11: Sí | N11: No | O11: No | Q11: No | S11: =IF(B11="","",IF(ISNUMBER(J11),IF(J11<=10,'Configuración'!$B$23,IF(J11<=50,'Configuración'!$B$24,IF(J11<=200,'Configuración'!$B$25,0))),0)) -> 4 | T11: =IF(B11="","",IF(ISNUMBER(SEARCH("information technology",I11))+ISNUMBER(SEARCH("software",I11))+ISNUMBER(SEARCH("internet",I11))+ISNUMBER(SEARCH("computer",I11))+ISNUMBER(SEARCH("saas",I11))+ISNUMBER(SEARCH("fintech",I11))+ISNUMBER(SEARCH("information services",I11))+ISNUMBER(SEARCH("telecommunications",I11))>0,'Configuración'!$B$27,'Configuración'!$B$28)) -> 12 | U11: =IF(B11="","",IF(ISNUMBER(SEARCH("CEO",C11))+ISNUMBER(SEARCH("Founder",C11))+ISNUMBER(SEARCH("Owner",C11))+ISNUMBER(SEARCH("Dueño",C11))+ISNUMBER(SEARCH("Director General",C11))+ISNUMBER(SEARCH("Presidente",C11))+ISNUMBER(SEARCH("President",C11))>0,'Configuración'!$B$31,IF(ISNUMBER(SEARCH("CMO",C11))+ISNUMBER(SEARCH("Chief Marketing",C11))+ISNUMBER(SEARCH("VP Marketing",C11))+ISNUMBER(SEARCH("Director de Marketing",C11))+ISNUMBER(SEARCH("Director Marketing",C11))+ISNUMBER(SEARCH("Head of Marketing",C11))+ISNUMBER(SEARCH("Head Marketing",C11))>0,'Configuración'!$B$32,IF(ISNUMBER(SEARCH("Marketing Manager",C11))+ISNUMBER(SEARCH("Gerente de Marketing",C11))+ISNUMBER(SEARCH("Growth Manager",C11))+ISNUMBER(SEARCH("Demand Gen",C11))+ISNUMBER(SEARCH("Marketing Lead",C11))>0,'Configuración'!$B$33,IF(ISNUMBER(SEARCH("COO",C11))+ISNUMBER(SEARCH("CFO",C11))+ISNUMBER(SEARCH("CTO",C11))+ISNUMBER(SEARCH("Chief Operating",C11))+ISNUMBER(SEARCH("Chief Financial",C11))+ISNUMBER(SEARCH("Gerente General",C11))+ISNUMBER(SEARCH("General Manager",C11))>0,'Configuración'!$B$34,'Configuración'!$B$35))))) -> 12 | V11: =IF(B11="","",IF(K11="Sí",'Configuración'!$B$5,0)+IF(L11="Semanal",'Configuración'!$B$6,IF(L11="Mensual",'Configuración'!$B$7,0))+IF(M11="Sí",'Configuración'!$B$8,0)+IF(N11="Sí",'Configuración'!$B$9,0)+IF(O11="Sí",'Configuración'!$B$10,0)+IF(P11="Sí",'Configuración'!$B$11,0)+IF(Q11="Sí",'Configuración'!$B$12,0)+S11+T11+U11) -> 52 | W11: =IF(B11="","",IF(V11>='Configuración'!$B$19,"A",IF(V11>='Configuración'!$B$20,"B",IF(V11>='Configuración'!$B$21,"C","Descarte")))) -> B
A12: =IF(B12="","",ROW()-2) -> 10 | B12: Andres | C12: Co-founder & Chief Corporate Officer | D12: Pantera Makers | E12: andres@panteramakers.com | F12: http://www.linkedin.com/in/andres-mejia-99337215 | G12: http://www.linkedin.com/company/panteramakers | H12: https://panteramakers.com | I12: management consulting | J12: 39 | K12: Sí | L12: Semanal | M12: Sí | N12: No | O12: No | Q12: No | S12: =IF(B12="","",IF(ISNUMBER(J12),IF(J12<=10,'Configuración'!$B$23,IF(J12<=50,'Configuración'!$B$24,IF(J12<=200,'Configuración'!$B$25,0))),0)) -> 4 | T12: =IF(B12="","",IF(ISNUMBER(SEARCH("information technology",I12))+ISNUMBER(SEARCH("software",I12))+ISNUMBER(SEARCH("internet",I12))+ISNUMBER(SEARCH("computer",I12))+ISNUMBER(SEARCH("saas",I12))+ISNUMBER(SEARCH("fintech",I12))+ISNUMBER(SEARCH("information services",I12))+ISNUMBER(SEARCH("telecommunications",I12))>0,'Configuración'!$B$27,'Configuración'!$B$28)) -> 4 | U12: =IF(B12="","",IF(ISNUMBER(SEARCH("CEO",C12))+ISNUMBER(SEARCH("Founder",C12))+ISNUMBER(SEARCH("Owner",C12))+ISNUMBER(SEARCH("Dueño",C12))+ISNUMBER(SEARCH("Director General",C12))+ISNUMBER(SEARCH("Presidente",C12))+ISNUMBER(SEARCH("President",C12))>0,'Configuración'!$B$31,IF(ISNUMBER(SEARCH("CMO",C12))+ISNUMBER(SEARCH("Chief Marketing",C12))+ISNUMBER(SEARCH("VP Marketing",C12))+ISNUMBER(SEARCH("Director de Marketing",C12))+ISNUMBER(SEARCH("Director Marketing",C12))+ISNUMBER(SEARCH("Head of Marketing",C12))+ISNUMBER(SEARCH("Head Marketing",C12))>0,'Configuración'!$B$32,IF(ISNUMBER(SEARCH("Marketing Manager",C12))+ISNUMBER(SEARCH("Gerente de Marketing",C12))+ISNUMBER(SEARCH("Growth Manager",C12))+ISNUMBER(SEARCH("Demand Gen",C12))+ISNUMBER(SEARCH("Marketing Lead",C12))>0,'Configuración'!$B$33,IF(ISNUMBER(SEARCH("COO",C12))+ISNUMBER(SEARCH("CFO",C12))+ISNUMBER(SEARCH("CTO",C12))+ISNUMBER(SEARCH("Chief Operating",C12))+ISNUMBER(SEARCH("Chief Financial",C12))+ISNUMBER(SEARCH("Gerente General",C12))+ISNUMBER(SEARCH("General Manager",C12))>0,'Configuración'!$B$34,'Configuración'!$B$35))))) -> 12 | V12: =IF(B12="","",IF(K12="Sí",'Configuración'!$B$5,0)+IF(L12="Semanal",'Configuración'!$B$6,IF(L12="Mensual",'Configuración'!$B$7,0))+IF(M12="Sí",'Configuración'!$B$8,0)+IF(N12="Sí",'Configuración'!$B$9,0)+IF(O12="Sí",'Configuración'!$B$10,0)+IF(P12="Sí",'Configuración'!$B$11,0)+IF(Q12="Sí",'Configuración'!$B$12,0)+S12+T12+U12) -> 56 | W12: =IF(B12="","",IF(V12>='Configuración'!$B$19,"A",IF(V12>='Configuración'!$B$20,"B",IF(V12>='Configuración'!$B$21,"C","Descarte")))) -> B
A13: =IF(B13="","",ROW()-2) -> 11 | B13: Andres | C13: CEO | D13: The Talent Tree S.A.S | E13: andres.morales@thetalenttree.com.co | F13: http://www.linkedin.com/in/andres-mauricio-morales | G13: http://www.linkedin.com/school/thetalenttreebyikenga-finanzaspersonales | H13: https://thetalenttree.com.co | I13: professional training & coaching | J13: 9 | K13: No | L13: Inactivo | M13: Sí | N13: Sí | O13: No | Q13: No | S13: =IF(B13="","",IF(ISNUMBER(J13),IF(J13<=10,'Configuración'!$B$23,IF(J13<=50,'Configuración'!$B$24,IF(J13<=200,'Configuración'!$B$25,0))),0)) -> 12 | T13: =IF(B13="","",IF(ISNUMBER(SEARCH("information technology",I13))+ISNUMBER(SEARCH("software",I13))+ISNUMBER(SEARCH("internet",I13))+ISNUMBER(SEARCH("computer",I13))+ISNUMBER(SEARCH("saas",I13))+ISNUMBER(SEARCH("fintech",I13))+ISNUMBER(SEARCH("information services",I13))+ISNUMBER(SEARCH("telecommunications",I13))>0,'Configuración'!$B$27,'Configuración'!$B$28)) -> 4 | U13: =IF(B13="","",IF(ISNUMBER(SEARCH("CEO",C13))+ISNUMBER(SEARCH("Founder",C13))+ISNUMBER(SEARCH("Owner",C13))+ISNUMBER(SEARCH("Dueño",C13))+ISNUMBER(SEARCH("Director General",C13))+ISNUMBER(SEARCH("Presidente",C13))+ISNUMBER(SEARCH("President",C13))>0,'Configuración'!$B$31,IF(ISNUMBER(SEARCH("CMO",C13))+ISNUMBER(SEARCH("Chief Marketing",C13))+ISNUMBER(SEARCH("VP Marketing",C13))+ISNUMBER(SEARCH("Director de Marketing",C13))+ISNUMBER(SEARCH("Director Marketing",C13))+ISNUMBER(SEARCH("Head of Marketing",C13))+ISNUMBER(SEARCH("Head Marketing",C13))>0,'Configuración'!$B$32,IF(ISNUMBER(SEARCH("Marketing Manager",C13))+ISNUMBER(SEARCH("Gerente de Marketing",C13))+ISNUMBER(SEARCH("Growth Manager",C13))+ISNUMBER(SEARCH("Demand Gen",C13))+ISNUMBER(SEARCH("Marketing Lead",C13))>0,'Configuración'!$B$33,IF(ISNUMBER(SEARCH("COO",C13))+ISNUMBER(SEARCH("CFO",C13))+ISNUMBER(SEARCH("CTO",C13))+ISNUMBER(SEARCH("Chief Operating",C13))+ISNUMBER(SEARCH("Chief Financial",C13))+ISNUMBER(SEARCH("Gerente General",C13))+ISNUMBER(SEARCH("General Manager",C13))>0,'Configuración'!$B$34,'Configuración'!$B$35))))) -> 12 | V13: =IF(B13="","",IF(K13="Sí",'Configuración'!$B$5,0)+IF(L13="Semanal",'Configuración'!$B$6,IF(L13="Mensual",'Configuración'!$B$7,0))+IF(M13="Sí",'Configuración'!$B$8,0)+IF(N13="Sí",'Configuración'!$B$9,0)+IF(O13="Sí",'Configuración'!$B$10,0)+IF(P13="Sí",'Configuración'!$B$11,0)+IF(Q13="Sí",'Configuración'!$B$12,0)+S13+T13+U13) -> 44 | W13: =IF(B13="","",IF(V13>='Configuración'!$B$19,"A",IF(V13>='Configuración'!$B$20,"B",IF(V13>='Configuración'!$B$21,"C","Descarte")))) -> B
A14: =IF(B14="","",ROW()-2) -> 12 | B14: Dora | C14: CEO | D14: PlugIT Solutions | E14: dora.mejia@plugitsolutions.com.co | F14: http://www.linkedin.com/in/dora-mejia-1231302a | G14: http://www.linkedin.com/company/plugit-solutions | H14: https://plugitsolutions.com.co | I14: information technology & services | J14: 3 | M14: Sí | R14: No se encuentra el perfil en Linkedin ni la página de la empresa | S14: =IF(B14="","",IF(ISNUMBER(J14),IF(J14<=10,'Configuración'!$B$23,IF(J14<=50,'Configuración'!$B$24,IF(J14<=200,'Configuración'!$B$25,0))),0)) -> 12 | T14: =IF(B14="","",IF(ISNUMBER(SEARCH("information technology",I14))+ISNUMBER(SEARCH("software",I14))+ISNUMBER(SEARCH("internet",I14))+ISNUMBER(SEARCH("computer",I14))+ISNUMBER(SEARCH("saas",I14))+ISNUMBER(SEARCH("fintech",I14))+ISNUMBER(SEARCH("information services",I14))+ISNUMBER(SEARCH("telecommunications",I14))>0,'Configuración'!$B$27,'Configuración'!$B$28)) -> 12 | U14: =IF(B14="","",IF(ISNUMBER(SEARCH("CEO",C14))+ISNUMBER(SEARCH("Founder",C14))+ISNUMBER(SEARCH("Owner",C14))+ISNUMBER(SEARCH("Dueño",C14))+ISNUMBER(SEARCH("Director General",C14))+ISNUMBER(SEARCH("Presidente",C14))+ISNUMBER(SEARCH("President",C14))>0,'Configuración'!$B$31,IF(ISNUMBER(SEARCH("CMO",C14))+ISNUMBER(SEARCH("Chief Marketing",C14))+ISNUMBER(SEARCH("VP Marketing",C14))+ISNUMBER(SEARCH("Director de Marketing",C14))+ISNUMBER(SEARCH("Director Marketing",C14))+ISNUMBER(SEARCH("Head of Marketing",C14))+ISNUMBER(SEARCH("Head Marketing",C14))>0,'Configuración'!$B$32,IF(ISNUMBER(SEARCH("Marketing Manager",C14))+ISNUMBER(SEARCH("Gerente de Marketing",C14))+ISNUMBER(SEARCH("Growth Manager",C14))+ISNUMBER(SEARCH("Demand Gen",C14))+ISNUMBER(SEARCH("Marketing Lead",C14))>0,'Configuración'!$B$33,IF(ISNUMBER(SEARCH("COO",C14))+ISNUMBER(SEARCH("CFO",C14))+ISNUMBER(SEARCH("CTO",C14))+ISNUMBER(SEARCH("Chief Operating",C14))+ISNUMBER(SEARCH("Chief Financial",C14))+ISNUMBER(SEARCH("Gerente General",C14))+ISNUMBER(SEARCH("General Manager",C14))>0,'Configuración'!$B$34,'Configuración'!$B$35))))) -> 12 | V14: =IF(B14="","",IF(K14="Sí",'Configuración'!$B$5,0)+IF(L14="Semanal",'Configuración'!$B$6,IF(L14="Mensual",'Configuración'!$B$7,0))+IF(M14="Sí",'Configuración'!$B$8,0)+IF(N14="Sí",'Configuración'!$B$9,0)+IF(O14="Sí",'Configuración'!$B$10,0)+IF(P14="Sí",'Configuración'!$B$11,0)+IF(Q14="Sí",'Configuración'!$B$12,0)+S14+T14+U14) -> 48 | W14: =IF(B14="","",IF(V14>='Configuración'!$B$19,"A",IF(V14>='Configuración'!$B$20,"B",IF(V14>='Configuración'!$B$21,"C","Descarte")))) -> B
A15: =IF(B15="","",ROW()-2) -> 13 | B15: Julian | C15: Co-Founder | D15: Legal E-Solutions | E15: julian-robayo@legalesolutions.com | F15: http://www.linkedin.com/in/juli%c3%a1n-robayo-19ab2073 | G15: http://www.linkedin.com/company/legal-e-solutions | H15: https://legalesolutions.com | I15: legal services | J15: 3 | K15: No | L15: Inactivo | M15: Sí | N15: No | O15: No | Q15: No | R15: CO-FOUNDER Ya no trabaja ahí | S15: =IF(B15="","",IF(ISNUMBER(J15),IF(J15<=10,'Configuración'!$B$23,IF(J15<=50,'Configuración'!$B$24,IF(J15<=200,'Configuración'!$B$25,0))),0)) -> 12 | T15: =IF(B15="","",IF(ISNUMBER(SEARCH("information technology",I15))+ISNUMBER(SEARCH("software",I15))+ISNUMBER(SEARCH("internet",I15))+ISNUMBER(SEARCH("computer",I15))+ISNUMBER(SEARCH("saas",I15))+ISNUMBER(SEARCH("fintech",I15))+ISNUMBER(SEARCH("information services",I15))+ISNUMBER(SEARCH("telecommunications",I15))>0,'Configuración'!$B$27,'Configuración'!$B$28)) -> 4 | U15: =IF(B15="","",IF(ISNUMBER(SEARCH("CEO",C15))+ISNUMBER(SEARCH("Founder",C15))+ISNUMBER(SEARCH("Owner",C15))+ISNUMBER(SEARCH("Dueño",C15))+ISNUMBER(SEARCH("Director General",C15))+ISNUMBER(SEARCH("Presidente",C15))+ISNUMBER(SEARCH("President",C15))>0,'Configuración'!$B$31,IF(ISNUMBER(SEARCH("CMO",C15))+ISNUMBER(SEARCH("Chief Marketing",C15))+ISNUMBER(SEARCH("VP Marketing",C15))+ISNUMBER(SEARCH("Director de Marketing",C15))+ISNUMBER(SEARCH("Director Marketing",C15))+ISNUMBER(SEARCH("Head of Marketing",C15))+ISNUMBER(SEARCH("Head Marketing",C15))>0,'Configuración'!$B$32,IF(ISNUMBER(SEARCH("Marketing Manager",C15))+ISNUMBER(SEARCH("Gerente de Marketing",C15))+ISNUMBER(SEARCH("Growth Manager",C15))+ISNUMBER(SEARCH("Demand Gen",C15))+ISNUMBER(SEARCH("Marketing Lead",C15))>0,'Configuración'!$B$33,IF(ISNUMBER(SEARCH("COO",C15))+ISNUMBER(SEARCH("CFO",C15))+ISNUMBER(SEARCH("CTO",C15))+ISNUMBER(SEARCH("Chief Operating",C15))+ISNUMBER(SEARCH("Chief Financial",C15))+ISNUMBER(SEARCH("Gerente General",C15))+ISNUMBER(SEARCH("General Manager",C15))>0,'Configuración'!$B$34,'Configuración'!$B$35))))) -> 12 | V15: =IF(B15="","",IF(K15="Sí",'Configuración'!$B$5,0)+IF(L15="Semanal",'Configuración'!$B$6,IF(L15="Mensual",'Configuración'!$B$7,0))+IF(M15="Sí",'Configuración'!$B$8,0)+IF(N15="Sí",'Configuración'!$B$9,0)+IF(O15="Sí",'Configuración'!$B$10,0)+IF(P15="Sí",'Configuración'!$B$11,0)+IF(Q15="Sí",'Configuración'!$B$12,0)+S15+T15+U15) -> 40 | W15: =IF(B15="","",IF(V15>='Configuración'!$B$19,"A",IF(V15>='Configuración'!$B$20,"B",IF(V15>='Configuración'!$B$21,"C","Descarte")))) -> B
A16: =IF(B16="","",ROW()-2) -> 14 | B16: Adriana | C16: CoFunder/CEO | D16: Cres-ko | E16: adriana@cres-ko.com | F16: http://www.linkedin.com/in/adriana-garcia-serrano | G16: http://www.linkedin.com/company/cres-ko | H16: https://cres-ko.com | I16: professional training & coaching | J16: 2 | K16: No | L16: Inactivo | M16: Sí | N16: No | O16: Sí | Q16: No | S16: =IF(B16="","",IF(ISNUMBER(J16),IF(J16<=10,'Configuración'!$B$23,IF(J16<=50,'Configuración'!$B$24,IF(J16<=200,'Configuración'!$B$25,0))),0)) -> 12 | T16: =IF(B16="","",IF(ISNUMBER(SEARCH("information technology",I16))+ISNUMBER(SEARCH("software",I16))+ISNUMBER(SEARCH("internet",I16))+ISNUMBER(SEARCH("computer",I16))+ISNUMBER(SEARCH("saas",I16))+ISNUMBER(SEARCH("fintech",I16))+ISNUMBER(SEARCH("information services",I16))+ISNUMBER(SEARCH("telecommunications",I16))>0,'Configuración'!$B$27,'Configuración'!$B$28)) -> 4 | U16: =IF(B16="","",IF(ISNUMBER(SEARCH("CEO",C16))+ISNUMBER(SEARCH("Founder",C16))+ISNUMBER(SEARCH("Owner",C16))+ISNUMBER(SEARCH("Dueño",C16))+ISNUMBER(SEARCH("Director General",C16))+ISNUMBER(SEARCH("Presidente",C16))+ISNUMBER(SEARCH("President",C16))>0,'Configuración'!$B$31,IF(ISNUMBER(SEARCH("CMO",C16))+ISNUMBER(SEARCH("Chief Marketing",C16))+ISNUMBER(SEARCH("VP Marketing",C16))+ISNUMBER(SEARCH("Director de Marketing",C16))+ISNUMBER(SEARCH("Director Marketing",C16))+ISNUMBER(SEARCH("Head of Marketing",C16))+ISNUMBER(SEARCH("Head Marketing",C16))>0,'Configuración'!$B$32,IF(ISNUMBER(SEARCH("Marketing Manager",C16))+ISNUMBER(SEARCH("Gerente de Marketing",C16))+ISNUMBER(SEARCH("Growth Manager",C16))+ISNUMBER(SEARCH("Demand Gen",C16))+ISNUMBER(SEARCH("Marketing Lead",C16))>0,'Configuración'!$B$33,IF(ISNUMBER(SEARCH("COO",C16))+ISNUMBER(SEARCH("CFO",C16))+ISNUMBER(SEARCH("CTO",C16))+ISNUMBER(SEARCH("Chief Operating",C16))+ISNUMBER(SEARCH("Chief Financial",C16))+ISNUMBER(SEARCH("Gerente General",C16))+ISNUMBER(SEARCH("General Manager",C16))>0,'Configuración'!$B$34,'Configuración'!$B$35))))) -> 12 | V16: =IF(B16="","",IF(K16="Sí",'Configuración'!$B$5,0)+IF(L16="Semanal",'Configuración'!$B$6,IF(L16="Mensual",'Configuración'!$B$7,0))+IF(M16="Sí",'Configuración'!$B$8,0)+IF(N16="Sí",'Configuración'!$B$9,0)+IF(O16="Sí",'Configuración'!$B$10,0)+IF(P16="Sí",'Configuración'!$B$11,0)+IF(Q16="Sí",'Configuración'!$B$12,0)+S16+T16+U16) -> 48 | W16: =IF(B16="","",IF(V16>='Configuración'!$B$19,"A",IF(V16>='Configuración'!$B$20,"B",IF(V16>='Configuración'!$B$21,"C","Descarte")))) -> B
A17: =IF(B17="","",ROW()-2) -> 15 | B17: Juan | C17: CEO Talenta Learning | D17: Talenta Learning | E17: jmcardona@talentalearning.com | F17: http://www.linkedin.com/in/juanmcardona | G17: http://www.linkedin.com/company/talenta-learning | H17: https://talentalearning.com | I17: e-learning | J17: 3 | K17: No | L17: Semanal | M17: No | N17: No | O17: No | Q17: No | S17: =IF(B17="","",IF(ISNUMBER(J17),IF(J17<=10,'Configuración'!$B$23,IF(J17<=50,'Configuración'!$B$24,IF(J17<=200,'Configuración'!$B$25,0))),0)) -> 12 | T17: =IF(B17="","",IF(ISNUMBER(SEARCH("information technology",I17))+ISNUMBER(SEARCH("software",I17))+ISNUMBER(SEARCH("internet",I17))+ISNUMBER(SEARCH("computer",I17))+ISNUMBER(SEARCH("saas",I17))+ISNUMBER(SEARCH("fintech",I17))+ISNUMBER(SEARCH("information services",I17))+ISNUMBER(SEARCH("telecommunications",I17))>0,'Configuración'!$B$27,'Configuración'!$B$28)) -> 4 | U17: =IF(B17="","",IF(ISNUMBER(SEARCH("CEO",C17))+ISNUMBER(SEARCH("Founder",C17))+ISNUMBER(SEARCH("Owner",C17))+ISNUMBER(SEARCH("Dueño",C17))+ISNUMBER(SEARCH("Director General",C17))+ISNUMBER(SEARCH("Presidente",C17))+ISNUMBER(SEARCH("President",C17))>0,'Configuración'!$B$31,IF(ISNUMBER(SEARCH("CMO",C17))+ISNUMBER(SEARCH("Chief Marketing",C17))+ISNUMBER(SEARCH("VP Marketing",C17))+ISNUMBER(SEARCH("Director de Marketing",C17))+ISNUMBER(SEARCH("Director Marketing",C17))+ISNUMBER(SEARCH("Head of Marketing",C17))+ISNUMBER(SEARCH("Head Marketing",C17))>0,'Configuración'!$B$32,IF(ISNUMBER(SEARCH("Marketing Manager",C17))+ISNUMBER(SEARCH("Gerente de Marketing",C17))+ISNUMBER(SEARCH("Growth Manager",C17))+ISNUMBER(SEARCH("Demand Gen",C17))+ISNUMBER(SEARCH("Marketing Lead",C17))>0,'Configuración'!$B$33,IF(ISNUMBER(SEARCH("COO",C17))+ISNUMBER(SEARCH("CFO",C17))+ISNUMBER(SEARCH("CTO",C17))+ISNUMBER(SEARCH("Chief Operating",C17))+ISNUMBER(SEARCH("Chief Financial",C17))+ISNUMBER(SEARCH("Gerente General",C17))+ISNUMBER(SEARCH("General Manager",C17))>0,'Configuración'!$B$34,'Configuración'!$B$35))))) -> 12 | V17: =IF(B17="","",IF(K17="Sí",'Configuración'!$B$5,0)+IF(L17="Semanal",'Configuración'!$B$6,IF(L17="Mensual",'Configuración'!$B$7,0))+IF(M17="Sí",'Configuración'!$B$8,0)+IF(N17="Sí",'Configuración'!$B$9,0)+IF(O17="Sí",'Configuración'!$B$10,0)+IF(P17="Sí",'Configuración'!$B$11,0)+IF(Q17="Sí",'Configuración'!$B$12,0)+S17+T17+U17) -> 40 | W17: =IF(B17="","",IF(V17>='Configuración'!$B$19,"A",IF(V17>='Configuración'!$B$20,"B",IF(V17>='Configuración'!$B$21,"C","Descarte")))) -> B
A18: =IF(B18="","",ROW()-2) -> 16 | B18: Camilo | C18: Co-founder | D18: Rentmies | E18: camilo@rentmies.com | F18: http://www.linkedin.com/in/camilo-gonzalez-alvarez-1514a615b | G18: http://www.linkedin.com/company/rentmies | H18: https://rentmies.com | I18: information technology & services | J18: 5 | K18: No | L18: Inactivo | M18: Sí | N18: Sí | O18: Sí | Q18: No | R18: Posible Tier 1 | S18: =IF(B18="","",IF(ISNUMBER(J18),IF(J18<=10,'Configuración'!$B$23,IF(J18<=50,'Configuración'!$B$24,IF(J18<=200,'Configuración'!$B$25,0))),0)) -> 12 | T18: =IF(B18="","",IF(ISNUMBER(SEARCH("information technology",I18))+ISNUMBER(SEARCH("software",I18))+ISNUMBER(SEARCH("internet",I18))+ISNUMBER(SEARCH("computer",I18))+ISNUMBER(SEARCH("saas",I18))+ISNUMBER(SEARCH("fintech",I18))+ISNUMBER(SEARCH("information services",I18))+ISNUMBER(SEARCH("telecommunications",I18))>0,'Configuración'!$B$27,'Configuración'!$B$28)) -> 12 | U18: =IF(B18="","",IF(ISNUMBER(SEARCH("CEO",C18))+ISNUMBER(SEARCH("Founder",C18))+ISNUMBER(SEARCH("Owner",C18))+ISNUMBER(SEARCH("Dueño",C18))+ISNUMBER(SEARCH("Director General",C18))+ISNUMBER(SEARCH("Presidente",C18))+ISNUMBER(SEARCH("President",C18))>0,'Configuración'!$B$31,IF(ISNUMBER(SEARCH("CMO",C18))+ISNUMBER(SEARCH("Chief Marketing",C18))+ISNUMBER(SEARCH("VP Marketing",C18))+ISNUMBER(SEARCH("Director de Marketing",C18))+ISNUMBER(SEARCH("Director Marketing",C18))+ISNUMBER(SEARCH("Head of Marketing",C18))+ISNUMBER(SEARCH("Head Marketing",C18))>0,'Configuración'!$B$32,IF(ISNUMBER(SEARCH("Marketing Manager",C18))+ISNUMBER(SEARCH("Gerente de Marketing",C18))+ISNUMBER(SEARCH("Growth Manager",C18))+ISNUMBER(SEARCH("Demand Gen",C18))+ISNUMBER(SEARCH("Marketing Lead",C18))>0,'Configuración'!$B$33,IF(ISNUMBER(SEARCH("COO",C18))+ISNUMBER(SEARCH("CFO",C18))+ISNUMBER(SEARCH("CTO",C18))+ISNUMBER(SEARCH("Chief Operating",C18))+ISNUMBER(SEARCH("Chief Financial",C18))+ISNUMBER(SEARCH("Gerente General",C18))+ISNUMBER(SEARCH("General Manager",C18))>0,'Configuración'!$B$34,'Configuración'!$B$35))))) -> 12 | V18: =IF(B18="","",IF(K18="Sí",'Configuración'!$B$5,0)+IF(L18="Semanal",'Configuración'!$B$6,IF(L18="Mensual",'Configuración'!$B$7,0))+IF(M18="Sí",'Configuración'!$B$8,0)+IF(N18="Sí",'Configuración'!$B$9,0)+IF(O18="Sí",'Configuración'!$B$10,0)+IF(P18="Sí",'Configuración'!$B$11,0)+IF(Q18="Sí",'Configuración'!$B$12,0)+S18+T18+U18) -> 60 | W18: =IF(B18="","",IF(V18>='Configuración'!$B$19,"A",IF(V18>='Configuración'!$B$20,"B",IF(V18>='Configuración'!$B$21,"C","Descarte")))) -> A
A19: =IF(B19="","",ROW()-2) -> 17 | B19: Andres | C19: Co-Founder | D19: Dantai Labs | E19: andres@dantailabs.com | F19: http://www.linkedin.com/in/andressarmiento | G19: http://www.linkedin.com/company/dantai-labs | H19: https://dantailabs.com | I19: information technology & services | J19: 3 | K19: No | L19: Inactivo | M19: Sí | N19: No | O19: No | Q19: No | R19: Posible Tier 1 | S19: =IF(B19="","",IF(ISNUMBER(J19),IF(J19<=10,'Configuración'!$B$23,IF(J19<=50,'Configuración'!$B$24,IF(J19<=200,'Configuración'!$B$25,0))),0)) -> 12 | T19: =IF(B19="","",IF(ISNUMBER(SEARCH("information technology",I19))+ISNUMBER(SEARCH("software",I19))+ISNUMBER(SEARCH("internet",I19))+ISNUMBER(SEARCH("computer",I19))+ISNUMBER(SEARCH("saas",I19))+ISNUMBER(SEARCH("fintech",I19))+ISNUMBER(SEARCH("information services",I19))+ISNUMBER(SEARCH("telecommunications",I19))>0,'Configuración'!$B$27,'Configuración'!$B$28)) -> 12 | U19: =IF(B19="","",IF(ISNUMBER(SEARCH("CEO",C19))+ISNUMBER(SEARCH("Founder",C19))+ISNUMBER(SEARCH("Owner",C19))+ISNUMBER(SEARCH("Dueño",C19))+ISNUMBER(SEARCH("Director General",C19))+ISNUMBER(SEARCH("Presidente",C19))+ISNUMBER(SEARCH("President",C19))>0,'Configuración'!$B$31,IF(ISNUMBER(SEARCH("CMO",C19))+ISNUMBER(SEARCH("Chief Marketing",C19))+ISNUMBER(SEARCH("VP Marketing",C19))+ISNUMBER(SEARCH("Director de Marketing",C19))+ISNUMBER(SEARCH("Director Marketing",C19))+ISNUMBER(SEARCH("Head of Marketing",C19))+ISNUMBER(SEARCH("Head Marketing",C19))>0,'Configuración'!$B$32,IF(ISNUMBER(SEARCH("Marketing Manager",C19))+ISNUMBER(SEARCH("Gerente de Marketing",C19))+ISNUMBER(SEARCH("Growth Manager",C19))+ISNUMBER(SEARCH("Demand Gen",C19))+ISNUMBER(SEARCH("Marketing Lead",C19))>0,'Configuración'!$B$33,IF(ISNUMBER(SEARCH("COO",C19))+ISNUMBER(SEARCH("CFO",C19))+ISNUMBER(SEARCH("CTO",C19))+ISNUMBER(SEARCH("Chief Operating",C19))+ISNUMBER(SEARCH("Chief Financial",C19))+ISNUMBER(SEARCH("Gerente General",C19))+ISNUMBER(SEARCH("General Manager",C19))>0,'Configuración'!$B$34,'Configuración'!$B$35))))) -> 12 | V19: =IF(B19="","",IF(K19="Sí",'Configuración'!$B$5,0)+IF(L19="Semanal",'Configuración'!$B$6,IF(L19="Mensual",'Configuración'!$B$7,0))+IF(M19="Sí",'Configuración'!$B$8,0)+IF(N19="Sí",'Configuración'!$B$9,0)+IF(O19="Sí",'Configuración'!$B$10,0)+IF(P19="Sí",'Configuración'!$B$11,0)+IF(Q19="Sí",'Configuración'!$B$12,0)+S19+T19+U19) -> 48 | W19: =IF(B19="","",IF(V19>='Configuración'!$B$19,"A",IF(V19>='Configuración'!$B$20,"B",IF(V19>='Configuración'!$B$21,"C","Descarte")))) -> B
A20: =IF(B20="","",ROW()-2) -> 18 | B20: Santiago | C20: Co-Founder | D20: Falcon | E20: santiago@falconapp.ai | F20: http://www.linkedin.com/in/aboutsantiago | G20: http://www.linkedin.com/company/falconapp | H20: https://falconapp.ai | I20: information technology & services | J20: 1 | K20: No | L20: Inactivo | M20: No | N20: No | O20: No | Q20: No | S20: =IF(B20="","",IF(ISNUMBER(J20),IF(J20<=10,'Configuración'!$B$23,IF(J20<=50,'Configuración'!$B$24,IF(J20<=200,'Configuración'!$B$25,0))),0)) -> 12 | T20: =IF(B20="","",IF(ISNUMBER(SEARCH("information technology",I20))+ISNUMBER(SEARCH("software",I20))+ISNUMBER(SEARCH("internet",I20))+ISNUMBER(SEARCH("computer",I20))+ISNUMBER(SEARCH("saas",I20))+ISNUMBER(SEARCH("fintech",I20))+ISNUMBER(SEARCH("information services",I20))+ISNUMBER(SEARCH("telecommunications",I20))>0,'Configuración'!$B$27,'Configuración'!$B$28)) -> 12 | U20: =IF(B20="","",IF(ISNUMBER(SEARCH("CEO",C20))+ISNUMBER(SEARCH("Founder",C20))+ISNUMBER(SEARCH("Owner",C20))+ISNUMBER(SEARCH("Dueño",C20))+ISNUMBER(SEARCH("Director General",C20))+ISNUMBER(SEARCH("Presidente",C20))+ISNUMBER(SEARCH("President",C20))>0,'Configuración'!$B$31,IF(ISNUMBER(SEARCH("CMO",C20))+ISNUMBER(SEARCH("Chief Marketing",C20))+ISNUMBER(SEARCH("VP Marketing",C20))+ISNUMBER(SEARCH("Director de Marketing",C20))+ISNUMBER(SEARCH("Director Marketing",C20))+ISNUMBER(SEARCH("Head of Marketing",C20))+ISNUMBER(SEARCH("Head Marketing",C20))>0,'Configuración'!$B$32,IF(ISNUMBER(SEARCH("Marketing Manager",C20))+ISNUMBER(SEARCH("Gerente de Marketing",C20))+ISNUMBER(SEARCH("Growth Manager",C20))+ISNUMBER(SEARCH("Demand Gen",C20))+ISNUMBER(SEARCH("Marketing Lead",C20))>0,'Configuración'!$B$33,IF(ISNUMBER(SEARCH("COO",C20))+ISNUMBER(SEARCH("CFO",C20))+ISNUMBER(SEARCH("CTO",C20))+ISNUMBER(SEARCH("Chief Operating",C20))+ISNUMBER(SEARCH("Chief Financial",C20))+ISNUMBER(SEARCH("Gerente General",C20))+ISNUMBER(SEARCH("General Manager",C20))>0,'Configuración'!$B$34,'Configuración'!$B$35))))) -> 12 | V20: =IF(B20="","",IF(K20="Sí",'Configuración'!$B$5,0)+IF(L20="Semanal",'Configuración'!$B$6,IF(L20="Mensual",'Configuración'!$B$7,0))+IF(M20="Sí",'Configuración'!$B$8,0)+IF(N20="Sí",'Configuración'!$B$9,0)+IF(O20="Sí",'Configuración'!$B$10,0)+IF(P20="Sí",'Configuración'!$B$11,0)+IF(Q20="Sí",'Configuración'!$B$12,0)+S20+T20+U20) -> 36 | W20: =IF(B20="","",IF(V20>='Configuración'!$B$19,"A",IF(V20>='Configuración'!$B$20,"B",IF(V20>='Configuración'!$B$21,"C","Descarte")))) -> C
A21: =IF(B21="","",ROW()-2) -> 19 | B21: Mariana | C21: Founder and Director | D21: Poderosas Colombia | E21: msanzdesantamaria@poderosascolombia.org | F21: http://www.linkedin.com/in/mariana-sanz-de-santamar%c3%ada-franco-72849b19a | G21: http://www.linkedin.com/company/poderosascolombia | H21: https://poderosascolombia.org | I21: civic & social organization | J21: 18 | K21: Sí | L21: Semanal | M21: Sí | N21: No | O21: No | Q21: No | S21: =IF(B21="","",IF(ISNUMBER(J21),IF(J21<=10,'Configuración'!$B$23,IF(J21<=50,'Configuración'!$B$24,IF(J21<=200,'Configuración'!$B$25,0))),0)) -> 4 | T21: =IF(B21="","",IF(ISNUMBER(SEARCH("information technology",I21))+ISNUMBER(SEARCH("software",I21))+ISNUMBER(SEARCH("internet",I21))+ISNUMBER(SEARCH("computer",I21))+ISNUMBER(SEARCH("saas",I21))+ISNUMBER(SEARCH("fintech",I21))+ISNUMBER(SEARCH("information services",I21))+ISNUMBER(SEARCH("telecommunications",I21))>0,'Configuración'!$B$27,'Configuración'!$B$28)) -> 4 | U21: =IF(B21="","",IF(ISNUMBER(SEARCH("CEO",C21))+ISNUMBER(SEARCH("Founder",C21))+ISNUMBER(SEARCH("Owner",C21))+ISNUMBER(SEARCH("Dueño",C21))+ISNUMBER(SEARCH("Director General",C21))+ISNUMBER(SEARCH("Presidente",C21))+ISNUMBER(SEARCH("President",C21))>0,'Configuración'!$B$31,IF(ISNUMBER(SEARCH("CMO",C21))+ISNUMBER(SEARCH("Chief Marketing",C21))+ISNUMBER(SEARCH("VP Marketing",C21))+ISNUMBER(SEARCH("Director de Marketing",C21))+ISNUMBER(SEARCH("Director Marketing",C21))+ISNUMBER(SEARCH("Head of Marketing",C21))+ISNUMBER(SEARCH("Head Marketing",C21))>0,'Configuración'!$B$32,IF(ISNUMBER(SEARCH("Marketing Manager",C21))+ISNUMBER(SEARCH("Gerente de Marketing",C21))+ISNUMBER(SEARCH("Growth Manager",C21))+ISNUMBER(SEARCH("Demand Gen",C21))+ISNUMBER(SEARCH("Marketing Lead",C21))>0,'Configuración'!$B$33,IF(ISNUMBER(SEARCH("COO",C21))+ISNUMBER(SEARCH("CFO",C21))+ISNUMBER(SEARCH("CTO",C21))+ISNUMBER(SEARCH("Chief Operating",C21))+ISNUMBER(SEARCH("Chief Financial",C21))+ISNUMBER(SEARCH("Gerente General",C21))+ISNUMBER(SEARCH("General Manager",C21))>0,'Configuración'!$B$34,'Configuración'!$B$35))))) -> 12 | V21: =IF(B21="","",IF(K21="Sí",'Configuración'!$B$5,0)+IF(L21="Semanal",'Configuración'!$B$6,IF(L21="Mensual",'Configuración'!$B$7,0))+IF(M21="Sí",'Configuración'!$B$8,0)+IF(N21="Sí",'Configuración'!$B$9,0)+IF(O21="Sí",'Configuración'!$B$10,0)+IF(P21="Sí",'Configuración'!$B$11,0)+IF(Q21="Sí",'Configuración'!$B$12,0)+S21+T21+U21) -> 56 | W21: =IF(B21="","",IF(V21>='Configuración'!$B$19,"A",IF(V21>='Configuración'!$B$20,"B",IF(V21>='Configuración'!$B$21,"C","Descarte")))) -> B
A22: =IF(B22="","",ROW()-2) -> 20 | B22: Laura | C22: Fundadora & CEO | D22: Kiper.ai | E22: laura@kiper.ai | F22: http://www.linkedin.com/in/lauranavarro91 | G22: http://www.linkedin.com/company/kiper-ai | H22: https://kipertienda.com | I22: information technology & services | J22: 5 | K22: No | L22: Inactivo | M22: Sí | N22: Sí | O22: No | Q22: No | R22: Posible Tier 1 | S22: =IF(B22="","",IF(ISNUMBER(J22),IF(J22<=10,'Configuración'!$B$23,IF(J22<=50,'Configuración'!$B$24,IF(J22<=200,'Configuración'!$B$25,0))),0)) -> 12 | T22: =IF(B22="","",IF(ISNUMBER(SEARCH("information technology",I22))+ISNUMBER(SEARCH("software",I22))+ISNUMBER(SEARCH("internet",I22))+ISNUMBER(SEARCH("computer",I22))+ISNUMBER(SEARCH("saas",I22))+ISNUMBER(SEARCH("fintech",I22))+ISNUMBER(SEARCH("information services",I22))+ISNUMBER(SEARCH("telecommunications",I22))>0,'Configuración'!$B$27,'Configuración'!$B$28)) -> 12 | U22: =IF(B22="","",IF(ISNUMBER(SEARCH("CEO",C22))+ISNUMBER(SEARCH("Founder",C22))+ISNUMBER(SEARCH("Owner",C22))+ISNUMBER(SEARCH("Dueño",C22))+ISNUMBER(SEARCH("Director General",C22))+ISNUMBER(SEARCH("Presidente",C22))+ISNUMBER(SEARCH("President",C22))>0,'Configuración'!$B$31,IF(ISNUMBER(SEARCH("CMO",C22))+ISNUMBER(SEARCH("Chief Marketing",C22))+ISNUMBER(SEARCH("VP Marketing",C22))+ISNUMBER(SEARCH("Director de Marketing",C22))+ISNUMBER(SEARCH("Director Marketing",C22))+ISNUMBER(SEARCH("Head of Marketing",C22))+ISNUMBER(SEARCH("Head Marketing",C22))>0,'Configuración'!$B$32,IF(ISNUMBER(SEARCH("Marketing Manager",C22))+ISNUMBER(SEARCH("Gerente de Marketing",C22))+ISNUMBER(SEARCH("Growth Manager",C22))+ISNUMBER(SEARCH("Demand Gen",C22))+ISNUMBER(SEARCH("Marketing Lead",C22))>0,'Configuración'!$B$33,IF(ISNUMBER(SEARCH("COO",C22))+ISNUMBER(SEARCH("CFO",C22))+ISNUMBER(SEARCH("CTO",C22))+ISNUMBER(SEARCH("Chief Operating",C22))+ISNUMBER(SEARCH("Chief Financial",C22))+ISNUMBER(SEARCH("Gerente General",C22))+ISNUMBER(SEARCH("General Manager",C22))>0,'Configuración'!$B$34,'Configuración'!$B$35))))) -> 12 | V22: =IF(B22="","",IF(K22="Sí",'Configuración'!$B$5,0)+IF(L22="Semanal",'Configuración'!$B$6,IF(L22="Mensual",'Configuración'!$B$7,0))+IF(M22="Sí",'Configuración'!$B$8,0)+IF(N22="Sí",'Configuración'!$B$9,0)+IF(O22="Sí",'Configuración'!$B$10,0)+IF(P22="Sí",'Configuración'!$B$11,0)+IF(Q22="Sí",'Configuración'!$B$12,0)+S22+T22+U22) -> 52 | W22: =IF(B22="","",IF(V22>='Configuración'!$B$19,"A",IF(V22>='Configuración'!$B$20,"B",IF(V22>='Configuración'!$B$21,"C","Descarte")))) -> B
A23: =IF(B23="","",ROW()-2) -> 21 | B23: Santiago | C23: CEO | D23: Keep Up | E23: svilladiego@keepup.news | F23: http://www.linkedin.com/in/santiagovilladiegomogollon | G23: http://www.linkedin.com/company/keepupagencia | H23: https://keepup.news | I23: information technology & services | J23: 38 | K23: No | L23: Semanal | M23: Sí | N23: No | O23: No | Q23: No | S23: =IF(B23="","",IF(ISNUMBER(J23),IF(J23<=10,'Configuración'!$B$23,IF(J23<=50,'Configuración'!$B$24,IF(J23<=200,'Configuración'!$B$25,0))),0)) -> 4 | T23: =IF(B23="","",IF(ISNUMBER(SEARCH("information technology",I23))+ISNUMBER(SEARCH("software",I23))+ISNUMBER(SEARCH("internet",I23))+ISNUMBER(SEARCH("computer",I23))+ISNUMBER(SEARCH("saas",I23))+ISNUMBER(SEARCH("fintech",I23))+ISNUMBER(SEARCH("information services",I23))+ISNUMBER(SEARCH("telecommunications",I23))>0,'Configuración'!$B$27,'Configuración'!$B$28)) -> 12 | U23: =IF(B23="","",IF(ISNUMBER(SEARCH("CEO",C23))+ISNUMBER(SEARCH("Founder",C23))+ISNUMBER(SEARCH("Owner",C23))+ISNUMBER(SEARCH("Dueño",C23))+ISNUMBER(SEARCH("Director General",C23))+ISNUMBER(SEARCH("Presidente",C23))+ISNUMBER(SEARCH("President",C23))>0,'Configuración'!$B$31,IF(ISNUMBER(SEARCH("CMO",C23))+ISNUMBER(SEARCH("Chief Marketing",C23))+ISNUMBER(SEARCH("VP Marketing",C23))+ISNUMBER(SEARCH("Director de Marketing",C23))+ISNUMBER(SEARCH("Director Marketing",C23))+ISNUMBER(SEARCH("Head of Marketing",C23))+ISNUMBER(SEARCH("Head Marketing",C23))>0,'Configuración'!$B$32,IF(ISNUMBER(SEARCH("Marketing Manager",C23))+ISNUMBER(SEARCH("Gerente de Marketing",C23))+ISNUMBER(SEARCH("Growth Manager",C23))+ISNUMBER(SEARCH("Demand Gen",C23))+ISNUMBER(SEARCH("Marketing Lead",C23))>0,'Configuración'!$B$33,IF(ISNUMBER(SEARCH("COO",C23))+ISNUMBER(SEARCH("CFO",C23))+ISNUMBER(SEARCH("CTO",C23))+ISNUMBER(SEARCH("Chief Operating",C23))+ISNUMBER(SEARCH("Chief Financial",C23))+ISNUMBER(SEARCH("Gerente General",C23))+ISNUMBER(SEARCH("General Manager",C23))>0,'Configuración'!$B$34,'Configuración'!$B$35))))) -> 12 | V23: =IF(B23="","",IF(K23="Sí",'Configuración'!$B$5,0)+IF(L23="Semanal",'Configuración'!$B$6,IF(L23="Mensual",'Configuración'!$B$7,0))+IF(M23="Sí",'Configuración'!$B$8,0)+IF(N23="Sí",'Configuración'!$B$9,0)+IF(O23="Sí",'Configuración'!$B$10,0)+IF(P23="Sí",'Configuración'!$B$11,0)+IF(Q23="Sí",'Configuración'!$B$12,0)+S23+T23+U23) -> 52 | W23: =IF(B23="","",IF(V23>='Configuración'!$B$19,"A",IF(V23>='Configuración'!$B$20,"B",IF(V23>='Configuración'!$B$21,"C","Descarte")))) -> B
A24: =IF(B24="","",ROW()-2) -> 22 | B24: Felipe | C24: Co-Founder | D24: Seeri | E24: fr@seeri.co | F24: http://www.linkedin.com/in/feliperacines | G24: http://www.linkedin.com/company/seeri | H24: https://seeri.co | I24: information technology & services | J24: 26 | K24: No | L24: Inactivo | M24: No | N24: No | O24: No | Q24: No | S24: =IF(B24="","",IF(ISNUMBER(J24),IF(J24<=10,'Configuración'!$B$23,IF(J24<=50,'Configuración'!$B$24,IF(J24<=200,'Configuración'!$B$25,0))),0)) -> 4 | T24: =IF(B24="","",IF(ISNUMBER(SEARCH("information technology",I24))+ISNUMBER(SEARCH("software",I24))+ISNUMBER(SEARCH("internet",I24))+ISNUMBER(SEARCH("computer",I24))+ISNUMBER(SEARCH("saas",I24))+ISNUMBER(SEARCH("fintech",I24))+ISNUMBER(SEARCH("information services",I24))+ISNUMBER(SEARCH("telecommunications",I24))>0,'Configuración'!$B$27,'Configuración'!$B$28)) -> 12 | U24: =IF(B24="","",IF(ISNUMBER(SEARCH("CEO",C24))+ISNUMBER(SEARCH("Founder",C24))+ISNUMBER(SEARCH("Owner",C24))+ISNUMBER(SEARCH("Dueño",C24))+ISNUMBER(SEARCH("Director General",C24))+ISNUMBER(SEARCH("Presidente",C24))+ISNUMBER(SEARCH("President",C24))>0,'Configuración'!$B$31,IF(ISNUMBER(SEARCH("CMO",C24))+ISNUMBER(SEARCH("Chief Marketing",C24))+ISNUMBER(SEARCH("VP Marketing",C24))+ISNUMBER(SEARCH("Director de Marketing",C24))+ISNUMBER(SEARCH("Director Marketing",C24))+ISNUMBER(SEARCH("Head of Marketing",C24))+ISNUMBER(SEARCH("Head Marketing",C24))>0,'Configuración'!$B$32,IF(ISNUMBER(SEARCH("Marketing Manager",C24))+ISNUMBER(SEARCH("Gerente de Marketing",C24))+ISNUMBER(SEARCH("Growth Manager",C24))+ISNUMBER(SEARCH("Demand Gen",C24))+ISNUMBER(SEARCH("Marketing Lead",C24))>0,'Configuración'!$B$33,IF(ISNUMBER(SEARCH("COO",C24))+ISNUMBER(SEARCH("CFO",C24))+ISNUMBER(SEARCH("CTO",C24))+ISNUMBER(SEARCH("Chief Operating",C24))+ISNUMBER(SEARCH("Chief Financial",C24))+ISNUMBER(SEARCH("Gerente General",C24))+ISNUMBER(SEARCH("General Manager",C24))>0,'Configuración'!$B$34,'Configuración'!$B$35))))) -> 12 | V24: =IF(B24="","",IF(K24="Sí",'Configuración'!$B$5,0)+IF(L24="Semanal",'Configuración'!$B$6,IF(L24="Mensual",'Configuración'!$B$7,0))+IF(M24="Sí",'Configuración'!$B$8,0)+IF(N24="Sí",'Configuración'!$B$9,0)+IF(O24="Sí",'Configuración'!$B$10,0)+IF(P24="Sí",'Configuración'!$B$11,0)+IF(Q24="Sí",'Configuración'!$B$12,0)+S24+T24+U24) -> 28 | W24: =IF(B24="","",IF(V24>='Configuración'!$B$19,"A",IF(V24>='Configuración'!$B$20,"B",IF(V24>='Configuración'!$B$21,"C","Descarte")))) -> C
